<robot
  name="arm_description">
  <link
    name="base_link">
    <inertial>
      <origin
        xyz="0.00857185004749454 0.0277890770314089 0.0379884681378223"
        rpy="0 0 0" />
      <mass
        value="0.0450462948917676" />
      <inertia
        ixx="0"
        ixy="0"
        ixz="0"
        iyy="0"
        iyz="0"
        izz="0" />
    </inertial>
    <visual>
      <origin
        xyz="0 0 0"
        rpy="0 0 0" />
      <geometry>
        <mesh
          filename="package://arm_description/meshes/base_link.STL" />
      </geometry>
      <material
        name="">
        <color
          rgba="0 0 1 0.5" />
      </material>
    </visual>
    <collision>
      <origin
        xyz="0 0 0"
        rpy="0 0 0" />
      <geometry>
        <mesh
          filename="package://arm_description/meshes/base_link.STL" />
      </geometry>
    </collision>
  </link>
  <link
    name="link1">
    <inertial>
      <origin
        xyz="0.110757629166325 -8.47845751938969E-12 8.47839506934456E-12"
        rpy="0 0 0" />
      <mass
        value="0.0483301725897621" />
      <inertia
        ixx="7.30576878083873E-06"
        ixy="-1.58332132490097E-15"
        ixz="1.58327752225683E-15"
        iyy="4.54361196205422E-05"
        iyz="8.37316539727175E-11"
        izz="3.81303508416227E-05" />
    </inertial>
    <visual>
      <origin
        xyz="0 0 0"
        rpy="0 0 0" />
      <geometry>
        <mesh
          filename="package://arm_description/meshes/link1.STL" />
      </geometry>
      <material
        name="">
        <color
          rgba="0.752941176470588 0.752941176470588 0.752941176470588 1" />
      </material>
    </visual>
    <collision>
      <origin
        xyz="0 0 0"
        rpy="0 0 0" />
      <geometry>
        <mesh
          filename="package://arm_description/meshes/link1.STL" />
      </geometry>
    </collision>
  </link>
  <joint
    name="joint1"
    type="continuous">
    <origin
      xyz="0.0085719 0.027789 0.020415"
      rpy="2.8348 -1.5708 0" />
    <parent
      link="base_link" />
    <child
      link="link1" />
    <axis
      xyz="1 0 0" />
  </joint>
  <link
    name="link2">
    <inertial>
      <origin
        xyz="0.0943407218386796 5.81092854593304E-07 -9.84910960427632E-07"
        rpy="0 0 0" />
      <mass
        value="0.0585758042581199" />
      <inertia
        ixx="1.46113815408979E-05"
        ixy="-3.52725056104033E-10"
        ixz="6.80793122545069E-11"
        iyy="0.00011990337254757"
        iyz="1.21656237397079E-10"
        izz="0.000119903479385558" />
    </inertial>
    <visual>
      <origin
        xyz="0 0 0"
        rpy="0 0 0" />
      <geometry>
        <mesh
          filename="package://arm_description/meshes/link2.STL" />
      </geometry>
      <material
        name="">
        <color
          rgba="0.752941176470588 0.752941176470588 0.752941176470588 1" />
      </material>
    </visual>
    <collision>
      <origin
        xyz="0 0 0"
        rpy="0 0 0" />
      <geometry>
        <mesh
          filename="package://arm_description/meshes/link2.STL" />
      </geometry>
    </collision>
  </link>
  <joint
    name="joint2"
    type="revolute">
    <origin
      xyz="0.18177 0 0"
      rpy="-1.5708 3.3307E-16 -1.7091" />
    <parent
      link="link1" />
    <child
      link="link2" />
    <axis
      xyz="0 -1 0" />
    <limit
      effort="0"
      velocity="0" />
  </joint>
  <link
    name="link3">
    <inertial>
      <origin
        xyz="0.0943408063355609 4.37197531261146E-07 -3.60101098773047E-07"
        rpy="0 0 0" />
      <mass
        value="0.0585758669634938" />
      <inertia
        ixx="1.46114629506271E-05"
        ixy="-2.88431244518703E-10"
        ixz="-8.17701402342981E-11"
        iyy="0.000119903710392333"
        iyz="1.32272864568619E-10"
        izz="0.000119903769241556" />
    </inertial>
    <visual>
      <origin
        xyz="0 0 0"
        rpy="0 0 0" />
      <geometry>
        <mesh
          filename="package://arm_description/meshes/link3.STL" />
      </geometry>
      <material
        name="">
        <color
          rgba="0.752941176470588 0.752941176470588 0.752941176470588 1" />
      </material>
    </visual>
    <collision>
      <origin
        xyz="0 0 0"
        rpy="0 0 0" />
      <geometry>
        <mesh
          filename="package://arm_description/meshes/link3.STL" />
      </geometry>
    </collision>
  </link>
  <joint
    name="joint3"
    type="revolute">
    <origin
      xyz="0.18177 0 0"
      rpy="-1.5708 2.3592E-16 -1.8796" />
    <parent
      link="link2" />
    <child
      link="link3" />
    <axis
      xyz="0 -1 0" />
    <limit
      effort="0"
      velocity="0" />
  </joint>
</robot>